## promise.catch后面的then还会执行吗
仍会执行
.catch(onRejected)内部调用了.then(underfined, onRejected)








































